Workbook
Name Slicer_Cell_Group: #REF!
Name Slicer_Cell_Group1: #REF!
Name Slicer_City_Address21: #REF!
Name Slicer_Cell_Group2: #REF!
Name Slicer_City_Address3: #REF!
Name Slicer_Department: #REF!
Name Slicer_City_Address1: #REF!
Name Slicer_City_Address: #REF!
Name Slicer_City_Address2: #REF!

Sheet Summary
B2: CHURCH MEMBERS PROFILING (Summary)
B5: TOTAL HEADCOUNT
B7: LM | C7: =COUNTA(LM!$K$5:$K$298) -> 183
B8: AMM | C8: =COUNTA(AMM!$K$5:$K$299) -> 76
B9: YOUTH | C9: =COUNTA(Youth!K5:K401) -> 192
B10: CHILDREN | C10: =COUNTA(Childrens!J5:J1001) -> 19
C11: =SUM(C7:C10) -> 470
C14: PROFILING FORM
C15: YES | D15: NO
B16: LM | C16: =COUNTIF(LM!$D$5:$D$298,"YES") -> 106 | D16: =COUNTIF(LM!$D$5:$D$298,"NO") -> 77 | E16: =C16+D16 -> 183
B17: AMM | C17: =COUNTIF(AMM!$D$5:$D$299,"YES") -> 49 | D17: =COUNTIF(AMM!$D$5:$D$299,"NO") -> 27 | E17: =C17+D17 -> 76
B18: YOUTH | C18: =COUNTIF(Youth!$D$5:$D$401,"YES") -> 90 | D18: =COUNTIF(Youth!$D$5:$D$401,"NO") -> 102 | E18: =C18+D18 -> 192
B19: CHILDREN

Sheet LM
A1: LADIES MINISTRIES DEPARTMENT
A3: Count per filter | B3: =SUBTOTAL(3,LM!$K$5:$K$298) -> 183
D4: With Profiling Forn | E4: Status | F4: Cell Group | G4: Age Group | H4: CG Position | I4: Full Name (Last, First) | J4: Last Name | K4: First Name | L4: Middle Initial | M4: Gender | N4: Street | O4: City Address | P4: Provincial Address | Q4: Contact Number | R4: Email | S4: Birthdate | T4: Age | U4: Birthplace | V4: Father | W4: Mother | X4: Baptized in Water | Y4: Date | Z4: Baptized in Holy Ghost | AA4: Date2 | AB4: Former Religious Affiliation | AC4: Educational Attaintment | AD4: Current Occupation | AE4: Church ministries (Present) | AF4: Church ministries (Past) | AG4: Personal skills | AH4: Sports Interest | AI4: Other skills | AJ4: Spouse Name | AK4: Spouse Occupation | AL4: Is you spouse a believer? | AM4: Do both of you attend the same church? | AN4: Emergency Contact | AO4: Address | AP4: Relationship | AQ4: Contact Number2
D5: Yes | F5: Palm | H5: Secretary | I5: =IF(AND(K5="",J5=""),"",CONCATENATE(J5,", ",K5)) -> Abuan, Christine | J5: Abuan | K5: Christine | L5: Villamin | M5: Female | N5: 14 Purok 8 Upper Km 5 | O5: Asin Road | P5: Paniqui, Tarlac | Q5: 0927-393-4928 | R5: cmvillamin.11@gmail.com | S5: 33970 | T5: =IF(S5="","",DATEDIF(S5,TODAY(),"Y")) -> 33 | U5: Quezon City | V5: Villamin, Martin Labasan | W5: Villamin, Irene Macadangdang | X5: Yes | Y5: November 11, 2009 | Z5: Yes | AA5: December 26, 2009 | AC5: College Level | AD5: Accountant | AE5: Music Ministry - Choir, Bible Quizzing Commission | AF5: Teaching, Music Ministry - Choir, Youth and Church Leader | AH5: Table Tennis | AJ5: Abuan, Jomar Caballero | AK5: Virtual Assistant | AL5: Yes | AM5: Yes | AN5: Abuan, Jomar | AO5: 14 Purok 8 Upper Km 5, Asin Rd | AP5: Spouse | AQ5: 0946-168-8476
D6: No | F6: Almond | H6: Member | I6: =IF(AND(K6="",J6=""),"",CONCATENATE(J6,", ",K6)) -> Abuan, Maria Fe | J6: Abuan | K6: Maria Fe | L6: Caballero | M6: Female | N6: 14 Purok 8 Upper Km 5 | O6: Asin Road | Q6: 0910-944-4093 | S6: 22531 | T6: =IF(S6="","",DATEDIF(S6,TODAY(),"Y")) -> 65
D7: No | F7: Juniper | H7: Member | I7: =IF(AND(K7="",J7=""),"",CONCATENATE(J7,", ",K7)) -> Akiapat, Felipa | J7: Akiapat | K7: Felipa | M7: Female | N7: MD 212 Longlong | O7: Puguis, La Trinidad | Q7: 0949-370-2539 | S7: 20718 | T7: =IF(S7="","",DATEDIF(S7,TODAY(),"Y")) -> 70
D8: Yes | F8: Acacia | H8: Leader | I8: =IF(AND(K8="",J8=""),"",CONCATENATE(J8,", ",K8)) -> Alarcio, Grace | J8: Alarcio | K8: Grace | M8: Female | N8: 11 Purok 8 Sampaguita Site | O8: San Luis Village | Q8: 0910-882-0715 | S8: 28065 | T8: =IF(S8="","",DATEDIF(S8,TODAY(),"Y")) -> 49 | U8: Ilocos Sur | V8: Aquino, Samuel | W8: Cofolan, Virginia | X8: Yes | Y8: December 1998 | Z8: Yes | AA8: December 1998 | AB8: Assembly of God | AC8: Vocational Course | AD8: Vendor | AE8: LM Cellgroup Secretary | AF8: Ushering Secretary | AI8: Tailoring | AJ8: Alarcio, Marcial | AK8: Driver | AL8: Yes | AM8: Yes | AN8: Alarcio, Marcial | AO8: 11 Purok 8 Sampaguita Site San Luis Village | AP8: Spouse | AQ8: 0950-516-2515
D9: Yes | F9: Acacia | H9: Member | I9: =IF(AND(K9="",J9=""),"",CONCATENATE(J9,", ",K9)) -> Alarcio, Kaye Cee | J9: Alarcio | K9: Kaye Cee | L9: D | M9: Female | N9: 11 Purok 8 Sampaguita Site | O9: San Luis Village | Q9: 0948-589-8500 | R9: kayeceedangca@gmail.com | S9: 35948 | T9: =IF(S9="","",DATEDIF(S9,TODAY(),"Y")) -> 28 | U9: Rosario, La Union | V9: Dangca, Edgardo | W9: Dangca, Tessie | X9: Yes | Y9: 2025 | Z9: Yes | AA9: February 23, 2025 | AB9: Roman Catholic | AC9: College Level | AD9: Vendor | AJ9: Alarcio, Laurence | AK9: Vendor | AL9: Yes | AM9: Yes | AN9: Alarcio, Laurence | AO9: Baguio City | AP9: Spouse | AQ9: 0963-888-1378
D10: Yes | F10: Cedar | H10: Assistant Leader | I10: =IF(AND(K10="",J10=""),"",CONCATENATE(J10,", ",K10)) -> Alcoriza, Jocelyn | J10: Alcoriza | K10: Jocelyn | M10: Female | O10: Goldfield, Itogon | Q10: 0946-625-8081 | S10: 27167 | T10: =IF(S10="","",DATEDIF(S10,TODAY(),"Y")) -> 52 | U10: Goldfield | V10: Estoe, Rudy | W10: Estoe, Teodora | X10: Yes | Y10: --- 19, 1994 | Z10: Yes | AA10: --- 19, 1994 | AJ10: Alcoriza, Reynaldo | AK10: Taxi Driver | AL10: Yes | AM10: Yes | AN10: Bentrez, Genera | AO10: Goldfield Itogon | AP10: Auntie
D11: Yes | F11: Almond | H11: Leader | I11: =IF(AND(K11="",J11=""),"",CONCATENATE(J11,", ",K11)) -> Aleo, Nena | J11: Aleo | K11: Nena | M11: Female | N11: AP 06B | O11: Ambiong Central, La Trinidad | Q11: 0949-820-4911 | S11: 20294 | T11: =IF(S11="","",DATEDIF(S11,TODAY(),"Y")) -> 71 | U11: Sagada Mt. Province | V11: Mastere, Eduardo | W11: Mastere, Neno Ogues | X11: Yes | Y11: August 1999 | Z11: Yes | AB11: Anglican | AC11: B.S. Commerce | AD11: Housewife | AG11: Photography, Gardening | AH11: Volleyball | AI11: Cooking | AJ11: Aleo, Alexander | AK11: Retired Military Officer | AL11: Not Yet | AN11: Aleo, Alexander | AO11: AP 06B Ambiong Central | AP11: Spouse
D12: Yes | F12: Almond | H12: Member | I12: =IF(AND(K12="",J12=""),"",CONCATENATE(J12,", ",K12)) -> Amistad, Hadassah Olive | J12: Amistad | K12: Hadassah Olive | L12: C | M12: Female | N12: 7 Purok 1 | O12: Irisan | Q12: 0946-457-5445 | R12: lovedatsima@gmail.com | S12: 31028 | T12: =IF(S12="","",DATEDIF(S12,TODAY(),"Y")) -> 41 | U12: Olongapo City | V12: Castro, Simplicio Jr. | W12: Castro, Rizalina | X12: Yes | Y12: November 1998 | Z12: Yes | AA12: December 1998 | AC12: College Undergrad | AE12: Children's Ministries | AF12: Ushering | AG12: Teaching, Arts and Deco, Baking | AH12: Volleyball | AI12: Cooking | AJ12: Amistad, Joseph Sinesin | AK12: Virtual Assistant | AL12: Yes | AM12: Yes | AN12: Amistad, Joseph Sinesin | AO12: 7 Purok 1 Irisan | AP12: Spouse | AQ12: 0918-502-8785
D13: No | F13: Sycamore | H13: Member | I13: =IF(AND(K13="",J13=""),"",CONCATENATE(J13,", ",K13)) -> Amistad, Jolie Mae | J13: Amistad | K13: Jolie Mae | M13: Female | T13: =IF(S13="","",DATEDIF(S13,TODAY(),"Y"))
D14: Yes | I14: =IF(AND(K14="",J14=""),"",CONCATENATE(J14,", ",K14)) -> Amplogio, Gina | J14: Amplogio | K14: Gina | L14: Odalio | M14: Female | N14: JB 51-G Capharan | O14: Pico, La Trinidad | R14: ginaamplogio4@gmail.com | S14: 24761 | T14: =IF(S14="","",DATEDIF(S14,TODAY(),"Y")) -> 59 | U14: Bauko, Mt. province | V14: Odalio, Carlos | W14: Odalio, Lolita | X14: Yes | Y14: 39371 | Z14: Yes | AB14: Roman Catholic | AC14: College Graduate | AD14: Self-employed | AG14: Teaching | AH14: Volleyball | AI14: Cooking | AJ14: Amplogio, Charlie | AK14: Self-employed | AL14: Yes | AM14: Yes | AN14: Naimes, Melecia | AO14: Lubas, La Trinidad | AP14: Sibling | AQ14: 0960-652-4642
D15: No | F15: Oak | H15: Member | I15: =IF(AND(K15="",J15=""),"",CONCATENATE(J15,", ",K15)) -> Ancheta, Jennylyn | J15: Ancheta | K15: Jennylyn | M15: Female | N15: 29 Avelino St | O15: Andres Bonifacio | Q15: 0945-094-6242 | S15: 22678 | T15: =IF(S15="","",DATEDIF(S15,TODAY(),"Y")) -> 64
D16: No | F16: Oak | H16: Member | I16: =IF(AND(K16="",J16=""),"",CONCATENATE(J16,", ",K16)) -> Andrada, Lolita | J16: Andrada | K16: Lolita | M16: Female | T16: =IF(S16="","",DATEDIF(S16,TODAY(),"Y"))
D17: Yes | F17: Sycamore | H17: Member | I17: =IF(AND(K17="",J17=""),"",CONCATENATE(J17,", ",K17)) -> Ano, Emiliana | J17: Ano | K17: Emiliana | L17: Cudlas | M17: Female | N17: 520 Purok 8 Badihoy St. | O17: Pinsao Proper | Q17: 0946-023-0167 | S17: 22090 | T17: =IF(S17="","",DATEDIF(S17,TODAY(),"Y")) -> 66 | U17: Burgos La Union | V17: Cudlas, Velasco Padilla | W17: Cayat, Marcelina Gacao | X17: Yes | Y17: June 28, 1998 | AB17: Roman Catholic | AC17: College Level | AD17: Personal Collection Dealer | AF17: LM Cellgroup Leader | AJ17: Ano, Albert Capuyan | AN17: Tagudin, Amie Ano | AO17: 520 Purok 8 Badihoy St. Pinsao Proper | AP17: Daughter
D18: Yes | F18: Almond | H18: Assistant Leader | I18: =IF(AND(K18="",J18=""),"",CONCATENATE(J18,", ",K18)) -> Apilada, Susan | J18: Apilada | K18: Susan | L18: B | M18: Female | N18: 057 Sitio Paltingan | O18: Ambiong, La Trinidad | P18: Tayug Pangasinan | Q18: 0935-997-6857 | S18: 23277 | T18: =IF(S18="","",DATEDIF(S18,TODAY(),"Y")) -> 63 | U18: Tayug Pangasinan | V18: Bermudez, Marcelo (+) | X18: Yes | Y18: February 2004 | Z18: Yes | AA18: March 2005 | AB18: Roman Catholic | AC18: High school level | AD18: Online selling direct | AI18: Cooking | AJ18: Apilada, Armando R. | AK18: Security Officer | AL18: Yes | AM18: Yes | AN18: Apilada, Armando R. | AO18: 057 Sitio Paltingan Ambiong La Trinidad | AP18: Spouse | AQ18: 0909-572-3317
D19: Yes | F19: Olive | H19: Member | I19: =IF(AND(K19="",J19=""),"",CONCATENATE(J19,", ",K19)) -> Aragon, Elaine Marie | J19: Aragon | K19: Elaine Marie | L19: W | M19: Female | N19: 8 De Tesis St | O19: Aurora Hill | Q19: 0994-157-8818 | S19: 33402 | T19: =IF(S19="","",DATEDIF(S19,TODAY(),"Y")) -> 35 | U19: Baguio City | V19: Wong, Benjamin Jr. | W19: Wong, Teofila | X19: Yes | Y19: July 14, 2000 | Z19: Yes | AC19: College Level | AD19: HR Officer at Good taste Otek | AE19: Music Ministry - Choir | AF19: Music Ministry - Choir, Youth adviser | AG19: Teaching, Singing | AH19: Volleyball | AI19: Cooking | AJ19: Aragon, Marc Andrew Revi | AK19: Dedurr Operator | AL19: Yes | AM19: Yes | AN19: Aragon, Marc Andrew Revi | AO19: 8 De Tesis St Aurora Hill | AP19: Spouse | AQ19: 0994-371-9691
D20: Yes | I20: =IF(AND(K20="",J20=""),"",CONCATENATE(J20,", ",K20)) -> Arcangel, Delia | J20: Arcangel | K20: Delia | L20: Larida | M20: Female | N20: Padre Zamora St Purok 2 | O20: Zamora St | P20: Negros Occidental | S20: 24473 | T20: =IF(S20="","",DATEDIF(S20,TODAY(),"Y")) -> 59 | U20: San Carlos Negros Occidental | V20: Larida, Hilardo Gripo | W20: Larida, Lovepta Cantojos | X20: Yes | Y20: March 13,2005 | Z20: Yes | AA20: September 18, 2005 | AB20: Protestant | AC20: Grade 2 | AD20: Beautician / Cooking | AG20: Singing | AH20: Basketball | AI20: Cooking, Tailoring | AJ20: Arcangel, Ramon Sr. | AL20: Not Yet | AM20: Not Yet | AN20: Mailare, Mona Jessica | AO20: Teachers Camp | AP20: Daughter
D21: No | F21: Mulberry | H21: Member | I21: =IF(AND(K21="",J21=""),"",CONCATENATE(J21,", ",K21)) -> Ayson, Cora | J21: Ayson | K21: Cora | M21: Female | T21: =IF(S21="","",DATEDIF(S21,TODAY(),"Y"))
D22: Yes | F22: Sycamore | H22: Member | I22: =IF(AND(K22="",J22=""),"",CONCATENATE(J22,", ",K22)) -> Ayungo, Ailene | J22: Ayungo | K22: Ailene | L22: Baydal | M22: Female | N22: 9 Tangerine Lane Avelino St. | O22: Fairview | P22: Antipolo Rizal | Q22: 0923-942-4149 / 0912-112-1123 | R22: ailenebaydal80@gmail.com | S22: 29483 | T22: =IF(S22="","",DATEDIF(S22,TODAY(),"Y")) -> 46 | U22: Putatan Muntinlupa Manila | V22: Baydal, Alejandro Mata | W22: Baydal, Evelyn España | X22: Yes | Z22: Yes | AC22: First year college | AD22: 4Life Research / Suntrust Properties Inc | AE22: Music Ministry - Choir | AF22: Music Ministry - Choir, Ushering | AG22: Arts and Deco, Photography | AH22: Volleyball | AI22: Cooking | AJ22: Ayungo, Martin Jr. | AK22: Personal driver, Project specialist | AL22: Yes | AM22: Yes | AN22: Ayungo, Martin Jr. | AO22: 9 Tangerine Lane Avelino St. Fairview | AP22: Spouse
D23: Yes | F23: Mulberry | H23: Member | I23: =IF(AND(K23="",J23=""),"",CONCATENATE(J23,", ",K23)) -> Bacsa, Hyneth Gwenn | J23: Bacsa | K23: Hyneth Gwenn | L23: B | M23: Female | N23: 048-B Boted | O23: Tawang, La Trinidad | Q23: 0967-301-6762 | R23: bryllevhien@gmail.com | S23: 37844 | T23: =IF(S23="","",DATEDIF(S23,TODAY(),"Y")) -> 23 | U23: La Trinidad Benguet | V23: Badilla, Brenson (+) | W23: Badilla, Beverly | X23: Yes | Z23: Yes | AC23: Tesda Graduate | AH23: Volleyball, Badminton | AI23: Baking | AJ23: Bacsa, Vhal | AL23: Yes | AM23: Not Yet | AN23: Badilla, Beverly | AO23: 048-B Boted Tawang La Trinidad | AP23: Mother
D24: Yes | F24: Pomegranate | H24: Assistant Leader | I24: =IF(AND(K24="",J24=""),"",CONCATENATE(J24,", ",K24)) -> Bagtilay, Lety | J24: Bagtilay | K24: Lety | M24: Female | N24: IC-121 KM 6 | O24: Betag, La Trinidad | Q24: 0912-190-4528 / 422-3285 | R24: letybagtilay9@gmail.com | S24: 22615 | T24: =IF(S24="","",DATEDIF(S24,TODAY(),"Y")) -> 64 | U24: Baguio City | V24: Mejia, Felix Sr. (+) | W24: Mejia, Virginia A (+) | X24: Yes | Y24: 40409 | Z24: Yes | AA24: 43784 | AB24: Roman Catholic | AC24: Secretarial Graduate | AE24: LM Cellgroup Assistant Leader | AG24: Singing | AJ24: Bagtilay, Jimmy (+) | AN24: Onalan, Milagros | AO24: IC-121 KM 6 Betag La Trinidad | AP24: Sister-in-law | AQ24: 0925-746-5573
D25: No | F25: Palm | H25: Member | I25: =IF(AND(K25="",J25=""),"",CONCATENATE(J25,", ",K25)) -> Balbino, Beverly | J25: Balbino | K25: Beverly | M25: Female | N25: Apugan | O25: Sto. Tomas | Q25: 0927-062-6427 | T25: =IF(S25="","",DATEDIF(S25,TODAY(),"Y"))
D26: No | F26: Sycamore | H26: Member | I26: =IF(AND(K26="",J26=""),"",CONCATENATE(J26,", ",K26)) -> Balinggan, Deborah | J26: Balinggan | K26: Deborah | M26: Female | T26: =IF(S26="","",DATEDIF(S26,TODAY(),"Y"))
D27: Yes | F27: Juniper | H27: Member | I27: =IF(AND(K27="",J27=""),"",CONCATENATE(J27,", ",K27)) -> Balinggan, Gene | J27: Balinggan | K27: Gene | M27: Female | N27: 154 BPI CPD | O27: Cresencia Village | P27: Shilan La Trinidad | Q27: 0939-918-6017 / 424-8932 | R27: gbalinggan@gmail.com | S27: 30952 | T27: =IF(S27="","",DATEDIF(S27,TODAY(),"Y")) -> 42 | U27: La Trinidad Benguet | V27: Tampoa, Rex | W27: Tampoa, Rufina | X27: Yes | Y27: December 2025 | Z27: Yes | AA27: 2006 | AB27: SDA | AC27: MA Psych | AD27: Instructor in UC | AG27: Teaching | AJ27: Balinggan, Jenkinson | AL27: Yes | AM27: Yes | AN27: Balinggan, Jenkinson | AO27: 154 BPI CPD Cresencia Village | AP27: Spouse | AQ27: 0939-918-6025
D28: No | F28: Oak | H28: Member | I28: =IF(AND(K28="",J28=""),"",CONCATENATE(J28,", ",K28)) -> Balinggan, Jubilee | J28: Balinggan | K28: Jubilee | L28: Bañez | M28: Female | N28: 154 BPI CPD | O28: Cresencia Village | Q28: 0998-988-8046 | S28: 31872 | T28: =IF(S28="","",DATEDIF(S28,TODAY(),"Y")) -> 39
D29: Yes | F29: Palm | H29: Member | I29: =IF(AND(K29="",J29=""),"",CONCATENATE(J29,", ",K29)) -> Balinggan, Mercedes | J29: Balinggan | K29: Mercedes | L29: Lucando | M29: Female | N29: Kabuyao | O29: Poblacion, Tuba | Q29: 0918-366-1587 | S29: 21269 | T29: =IF(S29="","",DATEDIF(S29,TODAY(),"Y")) -> 68 | U29: Kabuyao Pob. Tuba Benguet | V29: Lucando, Picoy (+) | W29: Lucando, Margarita (+) | X29: Yes | Z29: Yes | AB29: Roman Catholic | AC29: Midwifery Graduate | AE29: Church Elder | AF29: LM President | AH29: Volleyball | AJ29: Balinggan, Paul | AL29: Yes | AM29: Yes | AN29: Balinggan, Paul | AO29: Kabuyao Pob. Tuba Benguet | AP29: Spouse | AQ29: 0918-422-3882
D30: Yes | F30: Cedar | H30: Member | I30: =IF(AND(K30="",J30=""),"",CONCATENATE(J30,", ",K30)) -> Balneg, Rose | J30: Balneg | K30: Rose | L30: U | M30: Female | N30: Blk Lot 19B NHA | O30: Tadiangan, Tuba | Q30: 09219-75-9585 | S30: 26904 | T30: =IF(S30="","",DATEDIF(S30,TODAY(),"Y")) -> 53 | U30: Union, Madrid Surigao Del Sur | V30: Urbiztondo, Walfredo | W30: Urbiztondo, Pepita | X30: Yes | Y30: February 2, 2025 | AB30: Jesus is Lord | AI30: Cooking | AJ30: Balneg, Alfredo | AK30: Farmer | AL30: Yes | AM30: Yes | AN30: Balneg, Queen Crystalee | AO30: Blk Lot 19B NHA Housing | AP30: Daughter | AQ30: 0912-521-4964
D31: Yes | F31: Tamarisk | H31: Assistant Leader | I31: =IF(AND(K31="",J31=""),"",CONCATENATE(J31,", ",K31)) -> Bambao, Joanna | J31: Bambao | K31: Joanna | M31: Female | N31: 15 Balacbac Central | O31: Sto. Tomas Proper | S31: 29031 | T31: =IF(S31="","",DATEDIF(S31,TODAY(),"Y")) -> 47 | U31: Dagupan City, Pangasinan | V31: Caneng, Feliciano | W31: Caneng, Tomasa | X31: Yes | Y31: November 2, 2001 | Z31: Yes | AA31: June 1, 2002 | AB31: Roman Catholic | AC31: College Graduate | AJ31: Bambao, Angel Jr. | AK31: OFW | AL31: Yes | AM31: Yes | AN31: Bambao, Joanna / Bambao, KC | AO31: Balacbac | AP31: Spouse / Daughter | AQ31: 0912-186-2964 / 0969-386-4628
D32: No | F32: Hazelnut | H32: Secretary | I32: =IF(AND(K32="",J32=""),"",CONCATENATE(J32,", ",K32)) -> Banaag, Marjorie | J32: Banaag | K32: Marjorie | M32: Female | O32: Bakakeng Central | Q32: 0949-848-4774 | S32: 31130 | T32: =IF(S32="","",DATEDIF(S32,TODAY(),"Y")) -> 41
D33: No | F33: Tamarisk | H33: Member | I33: =IF(AND(K33="",J33=""),"",CONCATENATE(J33,", ",K33)) -> Bañares, Alicia Hafalla | J33: Bañares | K33: Alicia Hafalla | M33: Female | T33: =IF(S33="","",DATEDIF(S33,TODAY(),"Y"))
D34: No | F34: Sycamore | H34: Member | I34: =IF(AND(K34="",J34=""),"",CONCATENATE(J34,", ",K34)) -> Bañez, Gemma | J34: Bañez | K34: Gemma | M34: Female | T34: =IF(S34="","",DATEDIF(S34,TODAY(),"Y"))
D35: No | F35: Sycamore | H35: Member | I35: =IF(AND(K35="",J35=""),"",CONCATENATE(J35,", ",K35)) -> Bañez, Lucina | J35: Bañez | K35: Lucina | M35: Female | T35: =IF(S35="","",DATEDIF(S35,TODAY(),"Y"))
D36: No | F36: Almond | H36: Member | I36: =IF(AND(K36="",J36=""),"",CONCATENATE(J36,", ",K36)) -> Bangibang, Mila | J36: Bangibang | K36: Mila | M36: Female | N36: Block 21 NHA | O36: Tadiangan, Tuba | Q36: 0916-159-1002 | S36: 29953 | T36: =IF(S36="","",DATEDIF(S36,TODAY(),"Y")) -> 44
D37: Yes | F37: Pomegranate | H37: Member | I37: =IF(AND(K37="",J37=""),"",CONCATENATE(J37,", ",K37)) -> Bas-ilan, Benita | J37: Bas-ilan | K37: Benita | L37: B | M37: Female | N37: 048-B Boted | O37: Tawang, La Trinidad | Q37: 0909-576-2084 | S37: 21213 | T37: =IF(S37="","",DATEDIF(S37,TODAY(),"Y")) -> 68 | U37: Bangao, Buguias, Benguet | V37: Badilla, Pakito | W37: Badilla, Lumina | X37: Yes | Y37: November 18, 1998 | Z37: Yes | AA37: August 23, 1998 | AB37: Anglican | AC37: High school level | AI37: Cooking
D38: No | F38: Mulberry | H38: Member | I38: =IF(AND(K38="",J38=""),"",CONCATENATE(J38,", ",K38)) -> Batacan, Diane | J38: Batacan | K38: Diane | M38: Female | T38: =IF(S38="","",DATEDIF(S38,TODAY(),"Y"))
D39: No | F39: Cedar | H39: Member | I39: =IF(AND(K39="",J39=""),"",CONCATENATE(J39,", ",K39)) -> Bayla, Denise | J39: Bayla | K39: Denise | M39: Female | T39: =IF(S39="","",DATEDIF(S39,TODAY(),"Y"))
D40: Yes | F40: Cedar | H40: Member | I40: =IF(AND(K40="",J40=""),"",CONCATENATE(J40,", ",K40)) -> Bayla, Elizabeth | J40: Bayla | K40: Elizabeth | L40: L | M40: Female | N40: 27 Purok 4 | O40: Irisan | Q40: 0920-983-4258 | R40: elizabethbayla@gmail.com | S40: 25135 | T40: =IF(S40="","",DATEDIF(S40,TODAY(),"Y")) -> 58 | U40: Tuba, Benguet | V40: Lay-at, Samson Sr. | W40: Sugel, Francisca | X40: Yes | Y40: September 26, 1993 | Z40: Yes | AA40: September 26, 1993 | AB40: Roman Catholic | AC40: College Level | AD40: Athlete under PSC | AF40: Teaching, Bible Study | AG40: Teaching, Singing, Playing musical instrument, Literary Composition | AH40: Archery | AJ40: Bayla,Raigirando | AK40: OFW | AM40: Not Yet | AN40: Bayla, Kevin Anthony | AO40: 27 Purok 4 Irisan | AP40: Son | AQ40: 0927-765-1999
D41: Yes | I41: =IF(AND(K41="",J41=""),"",CONCATENATE(J41,", ",K41)) -> Bayla, Camile | J41: Bayla | K41: Camile | L41: F | M41: Female | N41: 27 Purok 4 | O41: Irisan | Q41: 0915-954-6909 | R41: sheethalfrigill@gmail.com | S41: 35100 | T41: =IF(S41="","",DATEDIF(S41,TODAY(),"Y")) -> 30 | U41: Baguio City | V41: Frigillana, Moreno | W41: Frigillana, Elizabeth | X41: Yes | Y41: 46102 | Z41: Yes | AA41: 46180 | AD41: Admin Officer - TESDA | AG41: Arts & Deco | AH41: Billiards | AI41: Welding | AJ41: Bayla, Eldrin Raig | AK41: Aircraft Mechanic | AL41: Yes | AM41: Yes | AN41: Bayla, Elrdin Raig | AO41: Same as home address | AP41: Spouse | AQ41: 0961-910-2180
...

Sheet AMM
A1: APOSTOLIC MEN'S MINISTRIES
A3: Count per filter | B3: =SUBTOTAL(3,AMM!$K$5:$K$299) -> 76
D4: With Profiling Forn | E4: Status | F4: Cell Group | G4: Age Group | H4: CG Position | I4: Full Name (Last, First) | J4: Last Name | K4: First Name | L4: Middle Initial | M4: Gender | N4: Street | O4: City Address | P4: Provincial Address | Q4: Contact Number | R4: Email | S4: Birthdate | T4: Age | U4: Birthplace | V4: Father | W4: Mother | X4: Baptized in Water | Y4: Date | Z4: Baptized in Holy Ghost | AA4: Date2 | AB4: Former Religious Affiliation | AC4: Educational Attaintment | AD4: Current Occupation | AE4: Church ministries (Present) | AF4: Church ministries (Past) | AG4: Personal skills | AH4: Sports Interest | AI4: Other skills | AJ4: Spouse Name | AK4: Spouse Occupation | AL4: Is your spouse a believer? | AM4: Do both of you attend the same church? | AN4: Emergency Contact | AO4: Address | AP4: Relationship | AQ4: Contact Number2
D5: Yes | F5: Judah | H5: Assistant Leader | I5: =IF(AND(K5="",J5=""),"",CONCATENATE(J5,", ",K5)) -> Abuan, Jomar | J5: Abuan | K5: Jomar | L5: C | M5: Male | N5: 14 Purok 8 Upper Km 5 | O5: Asin Road | P5: Baguio City | Q5: 0946-168-8476 | R5: shimaru26@gmail.com | S5: 33842 | T5: =IF(S5="","",DATEDIF(S5,TODAY(),"Y")) -> 34 | U5: Baguio City | V5: Abuan, Ricardo A. | W5: Abuan, Maria Fe C | X5: Yes | Z5: Yes | AE5: Music, BQC | AJ5: Abuan, Christine V. | AL5: Yes | AM5: Yes | AN5: Abuan, Christine V. | AO5: Same as Home Address | AP5: Spouse | AQ5: 0927-393-4928
D6: Yes | F6: Joseph | H6: Member | I6: =IF(AND(K6="",J6=""),"",CONCATENATE(J6,", ",K6)) -> Abuan, Ricardo | J6: Abuan | K6: Ricardo | L6: A | M6: Male | N6: 14 Purok 8 Upper Km 5 | O6: Asin Road | Q6: 0928-967-5947 | S6: 21665 | T6: =IF(S6="","",DATEDIF(S6,TODAY(),"Y")) -> 67
D7: Yes | F7: Issachar | H7: Member | I7: =IF(AND(K7="",J7=""),"",CONCATENATE(J7,", ",K7)) -> Alarcio, Marcial | J7: Alarcio | K7: Marcial | L7: L | M7: Male | N7: 11 Purok 8 Sampaguita Site | O7: San Luis Village | Q7: 0950-516-2515 | S7: 27089 | T7: =IF(S7="","",DATEDIF(S7,TODAY(),"Y")) -> 52 | U7: Manaoag, Pangasinan | W7: Lockiao, Paulina | X7: Yes | Z7: Yes | AB7: Roman Catholic | AC7: High School | AD7: Driver, Veg. Dealer | AJ7: Alarcio, Grace | AK7: Vendor | AL7: Yes | AM7: Yes | AN7: Alarcio, Grace | AO7: Same as Home Address | AP7: Spouse | AQ7: 0910-882-0715
D8: No | F8: Issachar | H8: Member | I8: =IF(AND(K8="",J8=""),"",CONCATENATE(J8,", ",K8)) -> Alcoriza, Reynaldo | J8: Alcoriza | K8: Reynaldo | M8: Male | N8: Goldfield | O8: Poblacion, Itogon | Q8: 0909-187-8704 | S8: 26467 | T8: =IF(S8="","",DATEDIF(S8,TODAY(),"Y")) -> 54
D9: No | H9: Member | I9: =IF(AND(K9="",J9=""),"",CONCATENATE(J9,", ",K9)) -> Alfornon, Bobby | J9: Alfornon | K9: Bobby | L9: A | M9: Male | N9: BULACAN | Q9: 0926-803-3837 | S9: 25305 | T9: =IF(S9="","",DATEDIF(S9,TODAY(),"Y")) -> 57
D10: Yes | F10: Benjamin | H10: Member | I10: =IF(AND(K10="",J10=""),"",CONCATENATE(J10,", ",K10)) -> Amistad, Joseph Sinesin | J10: Amistad | K10: Joseph Sinesin | L10: H | M10: Male | N10: 7 Purok 1 | O10: Irisan | Q10: 0918-502-8785 | R10: jamistad82@gmail.com | S10: 30079 | T10: =IF(S10="","",DATEDIF(S10,TODAY(),"Y")) -> 44 | U10: Baguio City | V10: Amistad, Snider Sr. | W10: Amistad, Rosemarie H. | X10: Yes | Y10: December 1996 | Z10: Yes | AA10: April 1997 | AB10: Roman Catholic | AC10: B.S.A. | AD10: V.A. - LG (Australia) | AE10: AMD, Music, Discipleship | AG10: Teaching | AJ10: Amistad, Hadassah Olive C. | AL10: Yes | AM10: Yes | AN10: Amistad, Hadassah Olive C. | AO10: Same as Home Address | AP10: Spouse | AQ10: 0946-457-5445
D11: No | I11: =IF(AND(K11="",J11=""),"",CONCATENATE(J11,", ",K11)) -> Amplogio, Charlie | J11: Amplogio | K11: Charlie | T11: =IF(S11="","",DATEDIF(S11,TODAY(),"Y"))
D12: No | F12: Dan | H12: Assistant Leader | I12: =IF(AND(K12="",J12=""),"",CONCATENATE(J12,", ",K12)) -> Ancheta, Cris | J12: Ancheta | K12: Cris | M12: Male | N12: 29 Avelino Street | O12: Fairview | Q12: 0942-040-6959 | R12: crisancheta@yahoo.com | S12: 23085 | T12: =IF(S12="","",DATEDIF(S12,TODAY(),"Y")) -> 63
D13: Yes | F13: Reuben | H13: Leader | I13: =IF(AND(K13="",J13=""),"",CONCATENATE(J13,", ",K13)) -> Apilada, Armando | J13: Apilada | K13: Armando | L13: R | M13: Male | N13: #057 Sitio Paltingan | O13: Ambiong, La Trinidad | P13: Brgy. Lipit Norte, Manaoag, Pangasinan | Q13: 0909-572-3317 | S13: 19731 | T13: =IF(S13="","",DATEDIF(S13,TODAY(),"Y")) -> 72 | U13: Manaoag, Pangasinan | V13: Apilada, Adriano N. | W13: Apilada, Gregoria R. | X13: Yes | Y13: February 2004 | Z13: Yes | AA13: March 2004 | AB13: Pentecostal Church of God | AC13: MSCRIM | AD13: Security Officer - UB | AE13: Bible Study - Ambiong and Bineng | AH13: Chess/ Dama | AI13: Painting, Cooking | AJ13: Apilada, Susan B. | AK13: Online Selling | AL13: Yes | AM13: Yes | AN13: Apilada, Susan B. | AO13: Same as Home Address | AP13: Spouse | AQ13: 0935-997-6857
D14: Yes | F14: Benjamin | H14: Member | I14: =IF(AND(K14="",J14=""),"",CONCATENATE(J14,", ",K14)) -> Aragon, Marc Andrew Reli | J14: Aragon | K14: Marc Andrew Reli | L14: M | M14: Male | N14: 8 De Tesis St | O14: Aurora Hill | P14: Los Banos, Laguna | Q14: 0994-371-9691 | S14: 34599 | T14: =IF(S14="","",DATEDIF(S14,TODAY(),"Y")) -> 32 | U14: Athens, Greece | V14: Aragon, Marcelino G. | W14: Aragon, Evangeline M. | X14: Yes | Z14: Yes | AC14: College Level | AD14: MOOG | AE14: CHOIR, Midweek Musician | AF14: Musician | AG14: Singing, Playing Musical Instruments | AH14: Volleyball, Basketball, Badminton, Chess | AI14: Carpentry, Painting, Cooking | AJ14: Aragon, Elaine Marie | AK14: HR Officer | AL14: Yes | AM14: Yes | AN14: Aragon, Elaine Marie | AO14: Same as Home Address | AP14: Spouse | AQ14: 0994-157-8808
D15: Yes | F15: Benjamin | H15: Member | I15: =IF(AND(K15="",J15=""),"",CONCATENATE(J15,", ",K15)) -> Ating, Dwight Paul | J15: Ating | K15: Dwight Paul | L15: C | M15: Male | N15: 33 Purok 8 | O15: Upper Pinget | Q15: 0968-686-9204 | R15: 06dwightpaul@gmail.com | S15: 36189 | T15: =IF(S15="","",DATEDIF(S15,TODAY(),"Y")) -> 27 | U15: Baguio City | V15: Ating, Domingo | W15: Cruz, Liza D. | X15: No | Z15: No | AB15: Roman Catholic | AC15: College Graduate | AD15: DENR - EMB ; EMS I | AH15: Baseball | AI15: Cooking
D16: Yes | F16: Levi | H16: Member | I16: =IF(AND(K16="",J16=""),"",CONCATENATE(J16,", ",K16)) -> Ayungo, Martin Jr | J16: Ayungo | K16: Martin Jr | L16: Charpang | M16: Male | N16: 421 Wednesday Alley | O16: Guisad Central | P16: Baguio City | Q16: 0916-936-4705 | R16: yogmartin@gmail.com | S16: 29831 | T16: =IF(S16="","",DATEDIF(S16,TODAY(),"Y")) -> 45 | U16: Natonin, Mt. Province | V16: Ayungo, Martin K. Sr. | W16: Ayungo, Margarita C. | X16: Yes | Z16: Yes | AB16: Roman Catholic | AC16: High School | AD16: On-Call Driver | AH16: Basketball, Chess/Dama | AJ16: Ayungo, Ailene Baydal | AK16: Entrepreneur | AL16: Yes | AM16: Yes | AN16: Ayungo, Ailene Baydal | AO16: Same as Home Address | AP16: Spouse
D17: Yes | F17: Benjamin | H17: Member | I17: =IF(AND(K17="",J17=""),"",CONCATENATE(J17,", ",K17)) -> Bacsa, Vhal | J17: Bacsa | K17: Vhal | M17: Male | N17: 048-B Boted | O17: Tawang, La Trinidad | P17: La Trinidad, Benguet | Q17: 0967-301-6762 | R17: bryllevhien@gmail.com | S17: 37666 | T17: =IF(S17="","",DATEDIF(S17,TODAY(),"Y")) -> 23 | U17: Baguio City | V17: Santos, Leonardo | W17: Bacsa, Theresa | X17: Yes | Y17: 45536 | Z17: Yes | AA17: 45505 | AC17: High School | AD17: Painter | AG17: Singing, Arts & Deco | AH17: Basketball, badminton | AI17: Painting, Cooking | AJ17: Bacsa, Hyneth Gwenn | AK17: Caregiver | AL17: Yes | AM17: Yes
D18: Yes | F18: Reuben | H18: Member | I18: =IF(AND(K18="",J18=""),"",CONCATENATE(J18,", ",K18)) -> Balinggan, Paul | J18: Balinggan | K18: Paul | L18: D | M18: Male | N18: Kabuyao | O18: Poblacion, Tuba | P18: Tuba, Benguet | Q18: 0918-722-5882 | S18: 19791 | T18: =IF(S18="","",DATEDIF(S18,TODAY(),"Y")) -> 72 | U18: Bakun, Benguet | V18: Balinggan, Pudico | W18: Pongga-as, Apinna | X18: Yes | Z18: Yes | AB18: Roman Catholic | AC18: B.S.N. | AJ18: Balinggan, Mercedes | AL18: Yes | AM18: Yes | AN18: Balinggan, Jurickson | AO18: 7 Lower P. Burgos Street, B.C. | AP18: Son
D19: No | I19: =IF(AND(K19="",J19=""),"",CONCATENATE(J19,", ",K19)) -> Balinggan, Jurickson | J19: Balinggan | K19: Jurickson | T19: =IF(S19="","",DATEDIF(S19,TODAY(),"Y"))
D20: No | H20: Member | I20: =IF(AND(K20="",J20=""),"",CONCATENATE(J20,", ",K20)) -> Bambao, Angel Jr | J20: Bambao | K20: Angel Jr | M20: Male | N20: Balacbac Central | O20: Sto. Tomas Proper | Q20: 0961-921-4697 | S20: 28859 | T20: =IF(S20="","",DATEDIF(S20,TODAY(),"Y")) -> 47
D21: No | F21: Dan | H21: Member | I21: =IF(AND(K21="",J21=""),"",CONCATENATE(J21,", ",K21)) -> Banaag, Gerald | J21: Banaag | K21: Gerald | M21: Male | N21: 120d Lower Kitma | O21: Bakakeng Central | Q21: 0920-858-9898 | R21: aldger8mj@yahoo.com | S21: 28459 | T21: =IF(S21="","",DATEDIF(S21,TODAY(),"Y")) -> 48
D22: No | I22: =IF(AND(K22="",J22=""),"",CONCATENATE(J22,", ",K22)) -> Bañez, Eugene | J22: Bañez | K22: Eugene | L22: C | N22: 7 | O22: Lower Padre Burgos St | T22: =IF(S22="","",DATEDIF(S22,TODAY(),"Y")) | X22: Yes | Z22: Yes | AJ22: Bañez, Gemma | AL22: Yes | AM22: Yes | AO22: Same as Home Address
D23: No | F23: Issachar | H23: Member | I23: =IF(AND(K23="",J23=""),"",CONCATENATE(J23,", ",K23)) -> Bayrante, Ramon | J23: Bayrante | K23: Ramon | L23: B | M23: Male | N23: CHURCH | Q23: 0992-207-7945 | R23: bayranteramon@gmail.com | S23: 24855 | T23: =IF(S23="","",DATEDIF(S23,TODAY(),"Y")) -> 58
D24: Yes | F24: Levi | H24: Leader | I24: =IF(AND(K24="",J24=""),"",CONCATENATE(J24,", ",K24)) -> Bentrez, Isaac | J24: Bentrez | K24: Isaac | M24: Male | N24: 123 Blk 3 | O24: Middle Quirino Hill | Q24: 0977-822-5999 | R24: bentrez231isaac@gmail.com | S24: 29823 | T24: =IF(S24="","",DATEDIF(S24,TODAY(),"Y")) -> 45 | U24: Poblacion, Itogon | V24: Bentrez, Larry Sr. | W24: Bentrez, Genera S. | X24: Yes | Z24: Yes | AC24: College Graduate | AD24: Teacher | AE24: BQM | AG24: Teaching, Literary Composition | AH24: Basketball, Chess/Dama | AI24: Cooking | AJ24: Bentrez, Jacqueline R. | AK24: Teacher | AL24: Yes | AM24: Yes | AN24: Bentrez, Jacqueline R. | AO24: Same as Home Address | AP24: Spouse | AQ24: 0927-211-0251
D25: Yes | F25: Reuben | H25: Member | I25: =IF(AND(K25="",J25=""),"",CONCATENATE(J25,", ",K25)) -> Boteng, Jaime | J25: Boteng | K25: Jaime | L25: S | M25: Male | O25: La Trinidad | P25: La Trinidad, Benguet | Q25: 0949-647-5784 | S25: 16789 | T25: =IF(S25="","",DATEDIF(S25,TODAY(),"Y")) -> 80 | U25: Tadian, Mountain Province | V25: Boteng, Peter | W25: Sibayan, Anita | X25: Yes | Y25: 35235 | Z25: Yes | AA25: 35235 | AB25: Anglican | AC25: Elementary | AI25: Carpentry Works | AJ25: Boteng, Sofia | AN25: Boteng, Angeline | AP25: Daughter | AQ25: 0949-647-5984
D26: Yes | F26: Joseph | H26: Member | I26: =IF(AND(K26="",J26=""),"",CONCATENATE(J26,", ",K26)) -> Cajigal, Rogelio | J26: Cajigal | K26: Rogelio | L26: O | M26: Male | N26: 4 AU/NPC | O26: Central Ambiong, La Trinidad | P26: Infanta, Pangasinan | Q26: 0906-245-1523 / 0994-659-8370 | R26: rogeliogaljica@gmail.com | S26: 22568 | T26: =IF(S26="","",DATEDIF(S26,TODAY(),"Y")) -> 65 | U26: Baguio City | V26: Cajigal, Melanio A. | W26: Cajigal, Erlinda O. | X26: Yes | Y26: 2023 | Z26: Yes | AB26: Roman Catholic | AC26: BS Civil Engineering Graduate | AD26: Retired | AG26: Teaching, Singing, Playing Musical instruments, Arts & Deco | AH26: Chess/ Dama | AI26: Carpentry Works, Mason, Painting, Cooking | AJ26: Cajigal, Nona | AK26: Housekeeper | AL26: Yes | AM26: Not Yet | AN26: Mago, Genno | AO26: 142 Purok 4, Lower Pinget | AP26: Co-employee
D27: Yes | H27: Member | I27: =IF(AND(K27="",J27=""),"",CONCATENATE(J27,", ",K27)) -> Calimlim, Jared | J27: Calimlim | K27: Jared | L27: B. | M27: Male | N27: 1 Purok 5 | O27: Holy Ghost Proper | P27: 524 Penged Nangalisan Tuba Benguet | Q27: 0945-976-6133 | R27: calimlimjared@yahoo.com.ph | S27: 32218 | T27: =IF(S27="","",DATEDIF(S27,TODAY(),"Y")) -> 38 | U27: Itogon Benguet | V27: Calimlim, Romulo | W27: Calimlim, Juliana | X27: Yes | Y27: 43408 | Z27: Yes | AA27: 43485 | AB27: Roman Catholic | AC27: College Graduate | AD27: Facilities Operations & Maintenance Tech. - T.I. | AE27: AMD; Choir | AG27: Singing; Playing Musical Instruments | AH27: Basketball | AI27: Building Wiring | AJ27: Calimlim, Jamielyn R. | AK27: House Wife | AL27: Yes | AM27: Yes | AN27: Calimlim, Jamielyn R. | AO27: Same as Home Address | AP27: Spouse | AQ27: 0963-888-1394
D28: No | F28: Dan | H28: Member | I28: =IF(AND(K28="",J28=""),"",CONCATENATE(J28,", ",K28)) -> Camodag, Audie | J28: Camodag | K28: Audie | M28: Male | O28: Middle Quirino Hill | Q28: 0938-627-6215 | S28: 26067 | T28: =IF(S28="","",DATEDIF(S28,TODAY(),"Y")) -> 55
D29: No | F29: Issachar | H29: Assistant Leader | I29: =IF(AND(K29="",J29=""),"",CONCATENATE(J29,", ",K29)) -> Caragay, Dennis | J29: Caragay | K29: Dennis | L29: A | M29: Male | N29: 126 | O29: Central Fairview | Q29: 0906-077-3464 | R29: denniscaragay34@gmail.com | S29: 29934 | T29: =IF(S29="","",DATEDIF(S29,TODAY(),"Y")) -> 44
D30: Yes | F30: Joseph | H30: Member | I30: =IF(AND(K30="",J30=""),"",CONCATENATE(J30,", ",K30)) -> Castro, Simplicio Jr | J30: Castro | K30: Simplicio Jr | L30: L | M30: Male | N30: 7 Purok 1 | O30: Irisan | Q30: 0946-051-3945 | S30: 21877 | T30: =IF(S30="","",DATEDIF(S30,TODAY(),"Y")) -> 66 | U30: Baguio City | V30: Castro, Simplicio Sr. | W30: Castro, Brigida | X30: Yes | Y30: 1998 | Z30: Yes | AA30: 1998 | AB30: Roman Catholic | AC30: High School | AD30: Businessman | AG30: Driver/Mechanic | AH30: Chess/ Dama | AI30: Carpentry Works, Mason, Welding | AJ30: Castro, Rizalina, Camora | AL30: Yes | AM30: Yes | AN30: Castro, Rizalina, Camora | AO30: Same as Home Address | AP30: Spouse
D31: Yes | F31: Judah | H31: Leader | I31: =IF(AND(K31="",J31=""),"",CONCATENATE(J31,", ",K31)) -> Cayandag, Jimmy | J31: Cayandag | K31: Jimmy | M31: Male | N31: 224 | O31: Poliwes | S31: 29168 | T31: =IF(S31="","",DATEDIF(S31,TODAY(),"Y")) -> 46 | U31: Itogon, Benguet | V31: Cayandag, Julian Sr. | W31: Cayandag, Lolita | X31: Yes | Y31: 2005 | Z31: Yes | AA31: 2005 | AB31: Roman Catholic | AC31: College Level | AD31: Gov't Employee - Baguio City Hall | AJ31: Cayandag, Marilou | AK31: Gov't Employee | AL31: Yes | AM31: Yes | AN31: Cayandag, Marilou | AO31: Same as Home Address | AP31: Spouse | AQ31: 0918-807-5193
D32: Yes | F32: Reuben | H32: Member | I32: =IF(AND(K32="",J32=""),"",CONCATENATE(J32,", ",K32)) -> Coyasan, Julio | J32: Coyasan | K32: Julio | L32: M | M32: Male | N32: OE26 Dengsi | O32: Tawang, La Trinidad | P32: Tawang, La Trinidad | Q32: 0939-567-3119 | S32: 23196 | T32: =IF(S32="","",DATEDIF(S32,TODAY(),"Y")) -> 63 | U32: Mankayan, Benguet | V32: Coyasan, Quintin | W32: Coyasan, Magdalina M. | X32: Yes | Y32: 34570 | Z32: Yes | AA32: 34570 | AC32: Vocational Graduate | AD32: Reflexologist | AG32: Singin, Playing Musical Instruments | AH32: Badminton, Chess/Dama | AI32: Carpentry Works, Welding | AJ32: Coyasan, Auxcinia R. | AK32: Housekeeper | AL32: Yes | AM32: Yes | AN32: Coyasan, Jayson | AO32: Same as Home Address | AP32: Son
D33: Yes | F33: Judah | H33: Member | I33: =IF(AND(K33="",J33=""),"",CONCATENATE(J33,", ",K33)) -> Coyasan, Priston | J33: Coyasan | K33: Priston | M33: Male | N33: 7 | O33: Pinsao Pilot Project | P33: Ambiong, La Trinidad | Q33: 0918-620-3449 | S33: 28111 | T33: =IF(S33="","",DATEDIF(S33,TODAY(),"Y")) -> 49 | U33: Mankayan, Benguet | V33: Coyasan, Quintin | W33: Coyasan, Magdalina M. | X33: Yes | Y33: 1998 | Z33: Yes | AA33: 2001 | AG33: Singing | AH33: Basketball | AI33: Carpentry Works | AJ33: Coyasan, Mary Jhoe | AL33: Yes | AM33: Yes | AN33: Coyasan, Mary Jhoe | AP33: Spouse
D34: No | F34: Levi | H34: Member | I34: =IF(AND(K34="",J34=""),"",CONCATENATE(J34,", ",K34)) -> Cruz, Aron | J34: Cruz | K34: Aron | M34: Male | N34: Block 3, 123 | O34: Middle Quirino Hill | Q34: 0956-276-5500 | S34: 30235 | T34: =IF(S34="","",DATEDIF(S34,TODAY(),"Y")) -> 44
D35: Yes | F35: Joseph | H35: Member | I35: =IF(AND(K35="",J35=""),"",CONCATENATE(J35,", ",K35)) -> Cutay, Digno | J35: Cutay | K35: Digno | L35: Gawec | M35: Male | N35: 27 Purok 5 F Cutay Drive | O35: Irisan | P35: Tadiangan Tuba, Benguet | Q35: 0910-922-5223 / 661-7508 | R35: cutaydigno@gmail.com | S35: 25149 | T35: =IF(S35="","",DATEDIF(S35,TODAY(),"Y")) -> 57 | U35: Tadian, Mountain Province | V35: Cutay, Frnandi Sr. | W35: Cutay, Fely | X35: Yes | Y35: 34337 | Z35: Yes | AA35: August 1994 | AB35: Roman Catholic | AC35: High School Graduate | AD35: Driver | AE35: AMM President | AF35: AMM Vice President | AH35: Volleyball | AJ35: Cutay, Regina A. | AK35: Housekeeper | AL35: Yes | AM35: Yes | AN35: Cutay, Regina A. | AO35: Same as Home Address | AP35: Spouse | AQ35: 0910-449-5756
D36: No | F36: Benjamin | H36: Assistant Leader | I36: =IF(AND(K36="",J36=""),"",CONCATENATE(J36,", ",K36)) -> Cutay, John Mark | J36: Cutay | K36: John Mark | L36: A | M36: Male | N36: CHURCH | P36: Suyoc Mankayan, Benguet | Q36: 0930-652-3111 | R36: cutayjohnmark@gmail.com | S36: 35600 | T36: =IF(S36="","",DATEDIF(S36,TODAY(),"Y")) -> 29 | U36: Mankayan, Benguet | V36: Cutay, Digno G. | W36: Cutay, Regina A. | X36: Yes | Y36: 2011 | Z36: Yes | AA36: 2011 | AC36: College Graduate | AD36: Quality Inspector - MOOG | AE36: Media Team | AF36: Ushering/Choir | AG36: Playing Musical Instruments | AH36: Basketball, Badminton, Chess/Dama | AJ36: Cutay, Johanna Faith B. | AK36: Finance/Teacher | AL36: Yes | AM36: Yes
D37: Yes | F37: Dan | H37: Member | I37: =IF(AND(K37="",J37=""),"",CONCATENATE(J37,", ",K37)) -> Dagupen, Franklin | J37: Dagupen | K37: Franklin | L37: C | M37: Male | N37: 19 Purok 28 | O37: Irisan | P37: Balakbak Kapangan, Benguet | Q37: 0918-358-7028 | R37: frada_eleot.sern@yahoo.com | S37: 26695 | T37: =IF(S37="","",DATEDIF(S37,TODAY(),"Y")) -> 53 | U37: Kapangan, Benguet | V37: Dagupen, Valdez | W37: Dagupen, Aurea Calpio | X37: Yes | Y37: 1994 | Z37: Yes | AA37: 2002 | AD37: Electrician | AJ37: Dagupen, Josephine | AK37: Vendor | AL37: Yes | AM37: Yes | AN37: Dagupen, Josephine | AO37: Same as Home Address | AP37: Spouse | AQ37: 0919-226-4571
D38: Yes | F38: Reuben | H38: Member | I38: =IF(AND(K38="",J38=""),"",CONCATENATE(J38,", ",K38)) -> Dangla, Constancio Jr | J38: Dangla | K38: Constancio Jr | L38: C | M38: Male | N38: NHA | O38: Tadiangan, Tuba | P38: Tadiangan Tuba, Benguet | Q38: 0901-491-3067 | S38: 23464 | T38: =IF(S38="","",DATEDIF(S38,TODAY(),"Y")) -> 62 | U38: Cervantes, Ilocos Sur | V38: Dangla, Paulino | W38: Dangla, Carmen | X38: Yes | Y38: August 1990 | Z38: Yes | AA38: 1998 | AB38: Roman Catholic | AC38: College Graduate | AI38: Mason, Laborer | AJ38: Dangla, Nancy Buya | AK38: Housekeeper | AL38: Yes | AM38: Yes | AN38: Dangla, Hiede Cattleyah | AO38: Same as Home Address | AP38: Daughter | AQ38: 0921-743-2975
D39: Yes | F39: Judah | H39: Member | I39: =IF(AND(K39="",J39=""),"",CONCATENATE(J39,", ",K39)) -> Daskeo, Klient Patrick | J39: Daskeo | K39: Klient Patrick | M39: Male | N39: Prk 6 Brookspoint | O39: Aurora Hill | P39: Tadian, Mt. Province | Q39: 0932-740-4983 | R39: klintong3766@gmail.com | S39: 30635 | T39: =IF(S39="","",DATEDIF(S39,TODAY(),"Y")) -> 42 | U39: Makati City | V39: Daskeo, Patrick | W39: Daskeo, Emma | X39: Yes | Y39: 41624 | Z39: Yes | AA39: 41594 | AC39: College Level | AD39: Online ESL Teacher | AE39: Choir, AMM | AF39: AMM | AG39: Teaching, Singing, Arts & Deco | AH39: Volleyball, Basketball | AI39: Mason, Cooking | AJ39: Daskeo, May | AK39: Elementary Teacher | AL39: Yes | AM39: Yes | AN39: Daskeo, May | AO39: Same as Home Address | AP39: Spouse | AQ39: 0960-613-3613
D40: Yes | F40: Issachar | H40: Leader | I40: =IF(AND(K40="",J40=""),"",CONCATENATE(J40,", ",K40)) -> De Castro, Marlon | J40: De Castro | K40: Marlon | L40: B | M40: Male | N40: 25B Purok 4 | O40: Bakakeng Norte | P40: Baguio City | Q40: 0917-972-0679 | S40: 29889 | T40: =IF(S40="","",DATEDIF(S40,TODAY(),"Y")) -> 44 | U40: Antipolo, Rizal | V40: De Castro, Alejandro | W40: De Castro, Nenita B. | X40: Yes | Y40: 35328 | Z40: Yes | AA40: 35426 | AB40: Apostolic Pentecostal Church | AC40: College Level | AD40: Apartment/ Transient Manager | AE40: Music, Sunday School | AF40: Ushering | AG40: Teaching, Singing | AH40: Volleyball, Chess/Dama | AI40: Carpentry Works, Cooking | AJ40: De Castro, Rebecca | AK40: Apartment/ Transient Manager | AL40: Yes | AM40: Yes | AN40: De Castro, Rebecca | AO40: Same as Home Address | AP40: Spouse | AQ40: 0906-378-5711
D41: No | F41: Judah | H41: Member | I41: =IF(AND(K41="",J41=""),"",CONCATENATE(J41,", ",K41)) -> De Guzman, Randy | J41: De Guzman | K41: Randy | L41: L | M41: Male | N41: OD 348 Banig | O41: Tawang, La Trinidad | R41: msjdeguzman07@gmail.com | S41: 26213 | T41: =IF(S41="","",DATEDIF(S41,TODAY(),"Y")) -> 55
...

Sheet Youth
A1: YOUTH MINISTRIES
A3: Count per filter | B3: =SUBTOTAL(3,Youth!$K$5:$K$401) -> 192
D4: With Profiling Forn | E4: Status | F4: Cell Group | G4: Age Group | H4: CG Position | I4: Full Name (Last, First) | J4: Last Name | K4: First Name | L4: Middle Initial | M4: Gender | N4: Street | O4: City Address | P4: Provincial Address | Q4: Contact Number | R4: Email | S4: Birthdate | T4: Age | U4: Birthplace | V4: Father | W4: Mother | X4: Baptized in Water | Y4: Date | Z4: Baptized in Holy Ghost | AA4: Date2 | AB4: Former Religious Affiliation | AC4: Home Church | AD4: Pastor's Name | AE4: Educational Attainment | AF4: School Name | AG4: School Organization | AH4: Occupation (if working) | AI4: Church ministries (Present) | AJ4: Ministry You Want To Be Part Of | AK4: Personal skills | AL4: Sports Interest | AM4: Other skills | AN4: YLTS/Sectional Youth Con - Times Attended | AO4: Y.C./District Youth Con - Times Attended | AP4: Emergency Contact | AQ4: Address | AR4: Relationship | AS4: Contact Number2
D5: No | E5: Other Church | F5: Joshua | H5: Member | I5: =IF(AND(K5="",J5=""),"",CONCATENATE(J5,", ",K5)) -> Agpalo, Charles | J5: Agpalo | K5: Charles | M5: Male | T5: =IF(S5="","",DATEDIF(S5,TODAY(),"Y"))
D6: No | E6: Sunday Goer | F6: Samuel | H6: Member | I6: =IF(AND(K6="",J6=""),"",CONCATENATE(J6,", ",K6)) -> Akiapat, Femy | J6: Akiapat | K6: Femy | M6: Female | T6: =IF(S6="","",DATEDIF(S6,TODAY(),"Y"))
D7: No | E7: Inactive | F7: Elijah | G7: Hyphen | H7: Member | I7: =IF(AND(K7="",J7=""),"",CONCATENATE(J7,", ",K7)) -> Albing, John Lee | J7: Albing | K7: John Lee | M7: Male | T7: =IF(S7="","",DATEDIF(S7,TODAY(),"Y"))
D8: Yes | E8: Active | F8: Paul | H8: Assistant Leader | I8: =IF(AND(K8="",J8=""),"",CONCATENATE(J8,", ",K8)) -> Albing, Amela Grace | J8: Albing | K8: Amela Grace | L8: W | M8: Female | N8: 15 Moran St | O8: Gibraltar | P8: Tadian, Mt. Province | Q8: 0985-088-5808 | R8: graziawazian@gmail.com | S8: 36187 | T8: =IF(S8="","",DATEDIF(S8,TODAY(),"Y")) -> 27 | U8: La Trinidad, Benguet | V8: Albing, Melanio Nga-an | W8: Albing, Agustina Wasian | X8: Yes | Y8: 39726 | Z8: Yes | AA8: 39558 | AE8: College Graduate | AF8: U.B. | AI8: Music, Children's Ministry | AP8: Albing, John Lee | AQ8: Same as Home Address | AR8: Brother | AS8: 0948-490-2424
D9: Yes | E9: Active | F9: Elijah | G9: Hyphen | H9: Leader | I9: =IF(AND(K9="",J9=""),"",CONCATENATE(J9,", ",K9)) -> Albing, Alpha May | J9: Albing | K9: Alpha May | L9: W | M9: Female | N9: 15 Moran St | O9: Gibraltar | P9: Tadian, Mt. Province | Q9: 0930-545-7458 | R9: alparito13@gmail.com | S9: 33888 | T9: =IF(S9="","",DATEDIF(S9,TODAY(),"Y")) -> 34 | U9: La Trinidad, Benguet | V9: Albing, Melanio Nga-an | W9: Albing, Agustina Wasian | X9: Yes | Z9: Yes | AB9: Roman Catholic | AE9: College | AF9: U.B. | AI9: Music, Children's Ministry | AP9: Albing, John Lee | AQ9: Same as Home Address | AR9: Brother | AS9: 0948-490-2424
D10: No | E10: Sunday Goer | F10: Samuel | H10: Member | I10: =IF(AND(K10="",J10=""),"",CONCATENATE(J10,", ",K10)) -> Alcantara, Axel | J10: Alcantara | K10: Axel | M10: Male | T10: =IF(S10="","",DATEDIF(S10,TODAY(),"Y"))
D11: No | E11: Inactive | F11: Elijah | H11: Member | I11: =IF(AND(K11="",J11=""),"",CONCATENATE(J11,", ",K11)) -> Alcoriza, Renalyn | J11: Alcoriza | K11: Renalyn | M11: Female | T11: =IF(S11="","",DATEDIF(S11,TODAY(),"Y"))
D12: No | E12: Inactive | F12: Elisha | H12: Member | I12: =IF(AND(K12="",J12=""),"",CONCATENATE(J12,", ",K12)) -> Alister, Jun | J12: Alister | K12: Jun | M12: Male | T12: =IF(S12="","",DATEDIF(S12,TODAY(),"Y"))
D13: No | E13: Sunday Goer | F13: Paul | H13: Member | I13: =IF(AND(K13="",J13=""),"",CONCATENATE(J13,", ",K13)) -> Amplogio, Zhoilo | J13: Amplogio | K13: Zhoilo | M13: Male | T13: =IF(S13="","",DATEDIF(S13,TODAY(),"Y"))
D14: No | E14: Sunday Goer | F14: Paul | H14: Member | I14: =IF(AND(K14="",J14=""),"",CONCATENATE(J14,", ",K14)) -> Amplogio, Harvey | J14: Amplogio | K14: Harvey | M14: Male | T14: =IF(S14="","",DATEDIF(S14,TODAY(),"Y"))
D15: No | E15: Inactive | F15: Samuel | H15: Member | I15: =IF(AND(K15="",J15=""),"",CONCATENATE(J15,", ",K15)) -> Antonio, Froxh Zion | J15: Antonio | K15: Froxh Zion | L15: a | M15: Male | T15: =IF(S15="","",DATEDIF(S15,TODAY(),"Y"))
D16: No | E16: Active | F16: Moses | H16: Member | I16: =IF(AND(K16="",J16=""),"",CONCATENATE(J16,", ",K16)) -> Apilada, Jairah May | J16: Apilada | K16: Jairah May | M16: Female | N16: Ap31 Sitio Paltingan | O16: Ambiong, La Trinidad | Q16: 0964-142-3946 | S16: 39863 | T16: =IF(S16="","",DATEDIF(S16,TODAY(),"Y")) -> 17 | U16: Cavite | V16: Apilada, Arnel B. | W16: Cañada, Joana R. | X16: Yes | Y16: 44394 | Z16: Yes | AA16: 44386 | AE16: Current | AF16: Doña Aurora NHS | AK16: Dancing | AL16: Volleyball | AP16: Apilada, Armando | AQ16: Same as Home Address | AR16: Grandfather | AS16: 0909-572-3317
D17: Yes | E17: Inactive | F17: Moses | H17: Member | I17: =IF(AND(K17="",J17=""),"",CONCATENATE(J17,", ",K17)) -> Apilada, Arman Angelo | J17: Apilada | K17: Arman Angelo | L17: B | M17: Male | N17: 057 Sitio Paltingan | O17: Ambiong, La Trinidad | P17: Manaoag, Pangasinan | Q17: 0966-533-0009 | S17: 37645 | T17: =IF(S17="","",DATEDIF(S17,TODAY(),"Y")) -> 23 | U17: Baguio City | V17: Apilada, Armando | W17: Apilada, Susan | X17: Yes | Z17: Yes | AB17: Roman Catholic | AE17: BS Architecture 5th Year | AF17: U.B. | AK17: Arts & Deco | AM17: Drawing | AP17: Apilada, Armando | AQ17: Same as Home Address | AR17: Father | AS17: 0909-572-3317
D18: No | I18: =IF(AND(K18="",J18=""),"",CONCATENATE(J18,", ",K18)) -> Apilada, Arbie | J18: Apilada | K18: Arbie | M18: Female | N18: AP31 Paltingan | O18: Ambiong, La Trinidad | P18: Tayug, Pangasinan | Q18: 0929-867-7178 | R18: arbie. apilada@gmail.com | T18: =IF(S18="","",DATEDIF(S18,TODAY(),"Y")) | U18: Tayug, Pangasinan | V18: Apilada, Armando | W18: Apilada, Susan | X18: Yes | Y18: 37605 | Z18: Yes | AA18: 37652 | AE18: College | AF18: U.B. | AH18: Tutor | AK18: Teaching | AL18: Volleyball | AN18: 1 | AO18: 1 | AP18: Apilada, Armando | AQ18: Same as Home Address | AR18: Father | AS18: 0909-572-3317
D19: No | E19: Sunday Goer | F19: Timothy | H19: Member | I19: =IF(AND(K19="",J19=""),"",CONCATENATE(J19,", ",K19)) -> Apolinario, Troy Kenneth | J19: Apolinario | K19: Troy Kenneth | M19: Male | T19: =IF(S19="","",DATEDIF(S19,TODAY(),"Y"))
D20: Yes | I20: =IF(AND(K20="",J20=""),"",CONCATENATE(J20,", ",K20)) -> Augusto, Guillian | J20: Augusto | K20: Guillian | L20: M | M20: Female | O20: Holy Ghost Extension | P20: Lagawe, Ifugao | Q20: 0949-601-7951 | R20: guillian.augusto@gmail.com | S20: 36910 | T20: =IF(S20="","",DATEDIF(S20,TODAY(),"Y")) -> 25 | U20: Lagawe, Ifugao | V20: Augusto, Gilbert P. | W20: Augusto, Janet M. | X20: Yes | Y20: 42005 | Z20: Yes | AC20: UPC Lagawe Church | AD20: Ptr. Joel Baracao | AE20: College Graduate | AF20: U.C. | AH20: Treasury, Chalet Baguio Hotel | AI20: Music | AK20: Singing, Playing Musical Instruments | AL20: Table Tennis | AM20: Crochet | AN20: 1 | AO20: 5 | AP20: Cabbigat, Jinky | AQ20: Same as Home Address | AR20: Church Mate | AS20: 0928-907-1302
D21: No | E21: Active | F21: Joseph | H21: Member | I21: =IF(AND(K21="",J21=""),"",CONCATENATE(J21,", ",K21)) -> Ayungo III, Martin Aileslee | J21: Ayungo III | K21: Martin Aileslee | L21: B | M21: Male | T21: =IF(S21="","",DATEDIF(S21,TODAY(),"Y"))
D22: Yes | E22: Active | F22: Joseph | H22: Assistant Leader | I22: =IF(AND(K22="",J22=""),"",CONCATENATE(J22,", ",K22)) -> Badilla, Hervie Kate | J22: Badilla | K22: Hervie Kate | M22: Female | N22: OB-048-B Bated | O22: Tawang, La Trinidad | P22: Tawang, La Trinidad | Q22: 0910-002-7493 | R22: bherviekate@gmail.com | S22: 36822 | T22: =IF(S22="","",DATEDIF(S22,TODAY(),"Y")) -> 26 | V22: Badilla, Brenson | W22: Badilla, Beverly | X22: Yes | Y22: October 2012 | Z22: Yes | AA22: 2013 | AE22: College TESDA Graduate | AH22: Caregiver | AI22: Ushering | AK22: Arts & Deco | AL22: Volleyball, Badminton | AM22: Cooking | AN22: 10 | AO22: 10 | AP22: Badilla, Beverly | AQ22: Same as Home Address | AR22: Mother
D23: Yes | I23: =IF(AND(K23="",J23=""),"",CONCATENATE(J23,", ",K23)) -> Bagaoisan, Divine Mercy | J23: Bagaoisan | K23: Divine Mercy | L23: R | M23: Female | N23: Salud Mitra | P23: Macanaya Aparri, Cagayan | Q23: 0961-705-8441 | R23: divinebagaoisan@gmail.com | S23: 39325 | T23: =IF(S23="","",DATEDIF(S23,TODAY(),"Y")) -> 19 | U23: Macanaya Aparri, Cagayan | V23: Bagaoisan, Charito | W23: Bagaoisan, Merlita | X23: Yes | Y23: 42102 | Z23: Yes | AA23: 42106 | AC23: UPC Tabernacle of Living Saints | AD23: Ptr. Charito Bagaoisan | AE23: College | AF23: U.B. | AI23: Music | AK23: Singing | AL23: Volleyball, Badminton | AM23: Cooking | AN23: 8 | AO23: 3 | AP23: Bagaoisan, Charito | AQ23: Macanaya Aparri, Cagayan | AR23: Father | AS23: 0975-322-8737
D24: No | I24: =IF(AND(K24="",J24=""),"",CONCATENATE(J24,", ",K24)) -> Baldoz, King Stevenlee | J24: Baldoz | K24: King Stevenlee | L24: C | M24: Male | P24: Paniqui, Tarla | Q24: 0912-280-6426 | S24: 38217 | T24: =IF(S24="","",DATEDIF(S24,TODAY(),"Y")) -> 22 | U24: Narvacan, Ilocos Sur | V24: Baldoz, Vincent B. | W24: Baldoz, Tewie C. | X24: Yes | Y24: 43330 | Z24: Yes | AC24: UPC Paniqui Church | AD24: Ptr. Lino Banaag | AE24: 1st Year College - Current | AF24: U.C. | AK24: Singing, Photographt | AL24: Volleyball, Badminton | AM24: Cooking | AN24: 3 | AO24: 5 | AP24: Baldoz, Queen Vite | AQ24: Same as Home Address | AR24: Sibling | AS24: 0910-612-6223
D25: Yes | E25: Sunday Goer | F25: Jacob | H25: Member | I25: =IF(AND(K25="",J25=""),"",CONCATENATE(J25,", ",K25)) -> Balinggan, Jadden Tredway | J25: Balinggan | K25: Jadden Tredway | M25: Male | N25: 154 BPI Cpd | O25: Cresencia Village | Q25: 0962-158-2646 | S25: 40957 | T25: =IF(S25="","",DATEDIF(S25,TODAY(),"Y")) -> 14 | U25: Baguio City | V25: Balinggan, Jenkinson | W25: Balinggan, Gene | X25: Yes | Y25: 45704 | Z25: Yes | AE25: Grade 7 - Current | AF25: U.C. | AL25: Basketball, Soccer, Karate | AP25: Balinggan, Gene | AQ25: Same as Home Address | AR25: Mother | AS25: 0939-918-6017
D26: No | E26: Sunday Goer | F26: Timothy | H26: Member | I26: =IF(AND(K26="",J26=""),"",CONCATENATE(J26,", ",K26)) -> Balinggan, Gabrielle Troi | J26: Balinggan | K26: Gabrielle Troi | L26: T | M26: Female | T26: =IF(S26="","",DATEDIF(S26,TODAY(),"Y"))
D27: No | I27: =IF(AND(K27="",J27=""),"",CONCATENATE(J27,", ",K27)) -> Balneg, Queen Crystalie | J27: Balneg | K27: Queen Crystalie | L27: U | M27: Female | N27: Blk 1 Lot 19B NHA | O27: Tadiangan, Tuba | P27: Tuba, Benguet | Q27: 0912-521-4964 | S27: 40641 | T27: =IF(S27="","",DATEDIF(S27,TODAY(),"Y")) -> 15 | V27: Balneg, Alfredo | W27: Balneg, Rose Urbiztundo | X27: Yes | Y27: 45697 | AE27: Grade 8 - Current | AF27: Educare College Inc. | AK27: Arts & Deco | AM27: Painting | AP27: Balneg, Rose | AQ27: Same as Home Address | AR27: Mother | AS27: 0921-975-9585
D28: Yes | E28: Active | F28: Timothy | H28: Member | I28: =IF(AND(K28="",J28=""),"",CONCATENATE(J28,", ",K28)) -> Bambao, Kristine Chloe | J28: Bambao | K28: Kristine Chloe | L28: C | M28: Female | N28: 15 Balacbac Central | O28: Sto. Tomas Proper | P28: Baguio City | Q28: 0969-386-4628 | R28: kc08bambao@gmail.com | S28: 39506 | T28: =IF(S28="","",DATEDIF(S28,TODAY(),"Y")) -> 18 | U28: Baguio City | V28: Bambao, Angel Jr. | W28: Bambao, Joanna | X28: Yes | Y28: 44828 | Z28: Yes | AA28: 44647 | AE28: Grade 11 - Current | AF28: UB High School | AG28: Girl Scout of the Phil. | AI28: Ushering | AK28: Speaker/Socialize | AL28: Badminton | AN28: 1 | AO28: 2 | AP28: Bambao, Joanna | AQ28: Same as Home Address | AR28: Mother | AS28: 0912-186-2964
D29: Yes | E29: Active | F29: Joseph | H29: Member | I29: =IF(AND(K29="",J29=""),"",CONCATENATE(J29,", ",K29)) -> Banaag, Geraldine Marijoe | J29: Banaag | K29: Geraldine Marijoe | L29: S | M29: Female | N29: 120D Lower Kitma Interior | O29: Bakakeng Central | Q29: 0910-519-3828 | R29: geraldine100908@gmail.com | S29: 39730 | T29: =IF(S29="","",DATEDIF(S29,TODAY(),"Y")) -> 18 | U29: Baguio City | V29: Banaag, Gerald C. | W29: Banaag, Marjorie S. | X29: Yes | Y29: 44765 | Z29: Yes | AA29: 45319 | AB29: UCCP | AE29: Grade 10 - Current | AF29: Phil. Science High School - CAR | AG29: PSHS CAR Baking Club Member | AI29: Ushering | AK29: Arts & Deco, Photography | AL29: Volleyball, Badminton | AN29: 1 | AO29: 3 | AP29: Banaag, Gerald | AQ29: Same as Home Address | AR29: Father | AS29: 0920-858-9898
D30: Yes | E30: Active | F30: Joseph | H30: Member | I30: =IF(AND(K30="",J30=""),"",CONCATENATE(J30,", ",K30)) -> Banaag, Aldgeryne Faith | J30: Banaag | K30: Aldgeryne Faith | L30: S | M30: Female | N30: 120D Lower Kitma Interior | O30: Bakakeng Central | Q30: 0910-519-3858 | R30: banaagaldgerynef@gmail.com | S30: 40722 | T30: =IF(S30="","",DATEDIF(S30,TODAY(),"Y")) -> 15 | U30: Baguio City | V30: Banaag, Gerald C. | W30: Banaag, Marjorie S. | X30: Yes | Y30: 44766 | Z30: Yes | AA30: 2023 | AB30: UCCP | AE30: Step Learning Academy | AF30: Phil. Science High School - CAR | AI30: Bible Quizzing | AK30: Playing Musical Instruments, Literary Composition | AL30: Volleyball, Chess/Dama | AN30: 1 | AO30: 0 | AP30: Banaag, Marjorie | AQ30: Same as Home Address | AR30: Mother | AS30: 0949-848-4774
D31: No | E31: Active | F31: Jacob | H31: Leader | I31: =IF(AND(K31="",J31=""),"",CONCATENATE(J31,", ",K31)) -> Bañez, Journey Ryan | J31: Bañez | K31: Journey Ryan | M31: Male | T31: =IF(S31="","",DATEDIF(S31,TODAY(),"Y"))
D32: Yes | E32: Active | F32: Isaac | H32: Assistant Leader | I32: =IF(AND(K32="",J32=""),"",CONCATENATE(J32,", ",K32)) -> Basilio, Gylrihs Gem | J32: Basilio | K32: Gylrihs Gem | L32: B | M32: Female | N32: Lot 7A Blk 2 Onyx St NPC | O32: Irisan | Q32: 0960-583-5959 | R32: ggem.bbasilio.2@gmail.com | S32: 37852 | T32: =IF(S32="","",DATEDIF(S32,TODAY(),"Y")) -> 23 | U32: Baguio City | V32: Basilio, George S. | W32: Basilio, Shirly B. | X32: Yes | Y32: 2016 | Z32: Yes | AA32: 2017 | AE32: 3rd Year College - Current | AF32: BSU La Trinidad | AG32: Enlgish Language & Literature Students Association | AI32: Sunday School, Media, Youth Ministires | AK32: Literary Composition, Arts & Deco | AM32: Painting, Tailoring/Dressmaking | AN32: 7 to 8 | AO32: 14 to 16 | AP32: Boteng, Jaime | AQ32: FC323 Central balili, L.T. | AR32: Grandfather | AS32: 0949-647-5784
D33: Yes | E33: Active | F33: Joshua | H33: Assistant Leader | I33: =IF(AND(K33="",J33=""),"",CONCATENATE(J33,", ",K33)) -> Basilio, Geryl Ann | J33: Basilio | K33: Geryl Ann | L33: B | M33: Female | N33: Lot 7A Blk 2 Onyx St NPC | O33: Irisan | P33: Benguet | Q33: 0969-225-9709 | R33: gerylbasilio2121@gmail.com | S33: 38350 | T33: =IF(S33="","",DATEDIF(S33,TODAY(),"Y")) -> 21 | U33: Baguio City | V33: Basilio, George S. | W33: Basilio, Shirly B. | X33: Yes | Y33: 2014 | Z33: Yes | AA33: 2014 | AE33: College | AF33: U.C. | AI33: Music, Youth Media | AK33: Playing Musical instruments, Arts & Deco | AN33: 3 + | AO33: 3 + | AP33: Basilio, Shirly B. | AR33: Mother | AS33: 0947-734-1549
D34: Yes | E34: Other Church | F34: Paul | H34: Member | I34: =IF(AND(K34="",J34=""),"",CONCATENATE(J34,", ",K34)) -> Batalao, Nathaniel | J34: Batalao | K34: Nathaniel | L34: S | M34: Male | N34: 44 | O34: New Lucban | P34: Loo Buguias Benguet | Q34: 0951-599-5210 | R34: nathanielbatalao@gmail.com | S34: 36703 | T34: =IF(S34="","",DATEDIF(S34,TODAY(),"Y")) -> 26 | U34: Buguias, Benguet | V34: Batalao, Jonathan Jr. | W34: Batalao, Doria | X34: Yes | Y34: 41421 | Z34: Yes | AC34: UPC Buguias | AD34: Ptr. Tony Mamolang | AE34: BSCE | AF34: S.L.U. | AI34: Music, Praise Team | AK34: Acting | AL34: Volleyball, basketball | AN34: 7 | AO34: 4 | AP34: Batalao, Jonathan B. | AQ34: Loo Buguias, Benguet | AR34: Sibling | AS34: 0950-142-8408
D35: Yes | E35: Other Church | F35: Joshua | H35: Member | I35: =IF(AND(K35="",J35=""),"",CONCATENATE(J35,", ",K35)) -> Batalao, Jonathan | J35: Batalao | K35: Jonathan | L35: S | M35: Male | N35: 44 | O35: New Lucban | P35: Loo Buguias Benguet | Q35: 0927-327-9192 | R35: batalaojonathan@gmail.com | S35: 35948 | T35: =IF(S35="","",DATEDIF(S35,TODAY(),"Y")) -> 28 | U35: Buguias, Benguet | V35: Batalao, Jonathan Jr. | W35: Batalao, Doria | X35: Yes | Y35: 2011 | Z35: Yes | AC35: UPC Buguias | AD35: Ptr. Tony Mamolang | AE35: Automotive Tech; BS Architecture | AF35: BSU Buguias; U.B. | AH35: Apprentice, Draftsman - B.C. | AI35: Usheing, Choir | AK35: Arts & Deco | AL35: Volleyball, Basketball | AN35: 7 | AO35: 2 | AP35: Batalao, Nathaniel B. | AQ35: Loo Buguias, Benguet | AR35: Sibling | AS35: 0951-599-5210
D36: No | E36: Sunday Goer | F36: Jacob | H36: Member | I36: =IF(AND(K36="",J36=""),"",CONCATENATE(J36,", ",K36)) -> Bokket, Nathaniel | J36: Bokket | K36: Nathaniel | M36: Male | T36: =IF(S36="","",DATEDIF(S36,TODAY(),"Y"))
D37: No | E37: Sunday Goer | F37: Joshua | H37: Member | I37: =IF(AND(K37="",J37=""),"",CONCATENATE(J37,", ",K37)) -> Bokket, Mark | J37: Bokket | K37: Mark | M37: Male | T37: =IF(S37="","",DATEDIF(S37,TODAY(),"Y"))
D38: No | E38: Bible Study | F38: Moses | H38: Member | I38: =IF(AND(K38="",J38=""),"",CONCATENATE(J38,", ",K38)) -> Bonilla, Mark Rener | J38: Bonilla | K38: Mark Rener | L38: C | M38: Male | T38: =IF(S38="","",DATEDIF(S38,TODAY(),"Y"))
D39: No | E39: Bible Study | F39: Moses | H39: Member | I39: =IF(AND(K39="",J39=""),"",CONCATENATE(J39,", ",K39)) -> Bonilla, Joshua | J39: Bonilla | K39: Joshua | L39: B | M39: Male | T39: =IF(S39="","",DATEDIF(S39,TODAY(),"Y"))
D40: Yes | I40: =IF(AND(K40="",J40=""),"",CONCATENATE(J40,", ",K40)) -> Bosque, Ara Mae | J40: Bosque | K40: Ara Mae | M40: Female | N40: San Mateo, South Luzon, Rizal | P40: San Mateo, South Luzon, Rizal | Q40: 0969-466-1551 | R40: arambosque@gmail.com | S40: 36334 | T40: =IF(S40="","",DATEDIF(S40,TODAY(),"Y")) -> 27 | U40: Quezon City | V40: Bosque, Wilfred | W40: Bosque, Vilma | X40: Yes | Y40: 40787 | Z40: Yes | AA40: 2012 | AC40: UPC-CAC San Ancdres Bukid Manila | AD40: Ptr. Justine Tagudin | AE40: Bachelors Degree | AH40: BMS Tech Suoervisor | AI40: Music, Youth Pres., Sunday School, Prayer Warrior, Ushering | AK40: Teaching, Arts & Deci | AN40: 5 | AO40: 3 | AP40: Bosque, Ara Maica | AQ40: San Mateo, South Luzon, Rizal | AR40: Sibling | AS40: 0916-422-3933
D41: No | E41: Bible Study | F41: Joshua | H41: Member | I41: =IF(AND(K41="",J41=""),"",CONCATENATE(J41,", ",K41)) -> Briones, Jonel | J41: Briones | K41: Jonel | M41: Male | T41: =IF(S41="","",DATEDIF(S41,TODAY(),"Y"))
...

Sheet Childrens
